Workbook

Sheet Read Me
A1: Barbourville, KY — Public EV Charging Station Analysis
B3: Prepared for: Barbourville City Tourism / City of Barbourville
B4: Prepared by: Mountain Association — Energy Team, Central Appalachia Internship Program
B5: Report period: July 12, 2025 – July 11, 2026 (12 months, ChargePoint dashboard export)
B6: Stations covered: BARBOURVILLE / CITY HALL (Level 3 / DCFC fast charger) and BARBOURVILLE / TOURISM (Level 2 charger), both on the Barbourville City Tourism ChargePoint account.
B7: These are two physically different chargers, so this workbook analyzes them separately first (Tourism (Level 2) and City Hall (Level 3) tabs - Tourism is the primary station of interest), then presents an All Stations Combined view (Daily Summary / Time of Day / Revenue / Visitor Origin tabs).
B8: Data sources
B9: • Energy-vs-Time-chart export — daily energy (kWh) delivered by the charger, ChargePoint dashboard (2 overlapping exports, deduplicated to 365 daily records).
B10: • Sessions export — 288 individual charging sessions: start/end time, energy delivered, peak power, payment method.
B11: • Charging Session Updates export — 1,119 fifteen-minute interval power readings tied to 278 of the sessions, used to measure how much of each session was actively drawing "car load" power.
B12: • Organization Statement export — 237 billed transactions with driver ZIP/county, revenue, fees, and payout — matched to sessions by transaction/session ID (235 of 237 matched).
B13: • GHG Savings chart (ChargePoint) — reference exhibit only; underlying data points are not machine-readable from the chart file, so figures from it are cited qualitatively, not recomputed.
B15: Key definitions & assumptions used throughout this workbook
... B39: • Raw - Sessions, Raw - Daily Energy, Raw - Zip-County-State — the underlying cleaned data every formula in this workbook points back to (Raw - Sessions column K identifies which station each session belongs to)

Sheet Dashboard
A1: Barbourville, KY — Public EV Charging: 12-Month Snapshot
A2: BARBOURVILLE / CITY HALL (Level 3 DCFC) + BARBOURVILLE / TOURISM (Level 2) | Jul 2025 - Jul 2026 | Prepared as a benchmark example of what a Level 2 charger could bring to a city
A4: Total Sessions | C4: Total Energy (kWh) | E4: Avg Energy / Day (kWh) | G4: Avg Energy / Active Day (kWh) | I4: Avg Power While Charging (kW) | K4: Total Revenue | M4: Owner Payout | O4: Out-of-State Sessions | Q4: Avg Session Length (min)
A5: =COUNTA('Raw - Sessions'!A5:A292) -> 288 | C5: =SUM('Raw - Sessions'!E5:E292) -> 6216.7055 | E5: =SUM('Raw - Sessions'!E5:E292)/'Daily Summary'!C5 -> 17.03207 | G5: =SUM('Raw - Sessions'!E5:E292)/SUM('Raw - Sessions'!AF5:AF292) -> 45.048591 | I5: =SUM('Raw - Sessions'!E5:E292)/SUM('Raw - Sessions'!D5:D292) -> 29.183252 | K5: =SUM('Raw - Sessions'!P5:P292) -> 4036.12 | M5: =SUM('Raw - Sessions'!Q5:Q292) -> 3415.92 | O5: =COUNTIFS('Raw - Sessions'!$O$5:$O$292,"<>",'Raw - Sessions'!$O$5:$O$292,"<>KY") -> 68 | Q5: =AVERAGE('Raw - Sessions'!D5:D292)*60 -> 44.379803
A9: Level 2 (Tourism) vs. Level 3 (City Hall) at a Glance
A10: Metric | B10: Tourism (Level 2) | C10: City Hall (Level 3) | D10: Combined
A11: Sessions | B11: =COUNTIF('Raw - Sessions'!$K$5:$K$292,"BARBOURVILLE / TOURISM") -> 49 | C11: =COUNTIF('Raw - Sessions'!$K$5:$K$292,"BARBOURVILLE / CITY HALL") -> 239 | D11: =COUNTA('Raw - Sessions'!$K$5:$K$292) -> 288
A12: Energy (kWh) | B12: =SUMIF('Raw - Sessions'!$K$5:$K$292,"BARBOURVILLE / TOURISM",'Raw - Sessions'!$E$5:$E$292) -> 392.20674 | C12: =SUMIF('Raw - Sessions'!$K$5:$K$292,"BARBOURVILLE / CITY HALL",'Raw - Sessions'!$E$5:$E$292) -> 5824.4988 | D12: =SUM('Raw - Sessions'!$E$5:$E$292) -> 6216.7055
A13: Active Days (kWh > 0) | B13: =SUMIF('Raw - Sessions'!$K$5:$K$292,"BARBOURVILLE / TOURISM",'Raw - Sessions'!$AG$5:$AG$292) -> 27 | C13: =SUMIF('Raw - Sessions'!$K$5:$K$292,"BARBOURVILLE / CITY HALL",'Raw - Sessions'!$AG$5:$AG$292) -> 127 | D13: =SUM('Raw - Sessions'!$AF$5:$AF$292) -> 138
A14: Avg Energy / Day (kWh) | B14: =SUMIF('Raw - Sessions'!$K$5:$K$292,"BARBOURVILLE / TOURISM",'Raw - Sessions'!$E$5:$E$292)/'Daily Summary'!C5 -> 1.074539 | C14: =SUMIF('Raw - Sessions'!$K$5:$K$292,"BARBOURVILLE / CITY HALL",'Raw - Sessions'!$E$5:$E$292)/'Daily Summary'!C5 -> 15.957531 | D14: =SUM('Raw - Sessions'!$E$5:$E$292)/'Daily Summary'!C5 -> 17.03207
A15: Avg Energy / Active Day (kWh) | B15: =SUMIF('Raw - Sessions'!$K$5:$K$292,"BARBOURVILLE / TOURISM",'Raw - Sessions'!$E$5:$E$292)/SUMIF('Raw - Sessions'!$K$5:$K$292,"BARBOURVILLE / TOURISM",'Raw - Sessions'!$AG$5:$AG$292) -> 14.526176 | C15: =SUMIF('Raw - Sessions'!$K$5:$K$292,"BARBOURVILLE / CITY HALL",'Raw - Sessions'!$E$5:$E$292)/SUMIF('Raw - Sessions'!$K$5:$K$292,"BARBOURVILLE / CITY HALL",'Raw - Sessions'!$AG$5:$AG$292) -> 45.862195 | D15: =SUM('Raw - Sessions'!$E$5:$E$292)/SUM('Raw - Sessions'!$AF$5:$AF$292) -> 45.048591
A16: Avg Power While Charging (kW) | B16: =SUMIF('Raw - Sessions'!$K$5:$K$292,"BARBOURVILLE / TOURISM",'Raw - Sessions'!$E$5:$E$292)/SUMIF('Raw - Sessions'!$K$5:$K$292,"BARBOURVILLE / TOURISM",'Raw - Sessions'!$D$5:$D$292) -> 6.1936888 | C16: =SUMIF('Raw - Sessions'!$K$5:$K$292,"BARBOURVILLE / CITY HALL",'Raw - Sessions'!$E$5:$E$292)/SUMIF('Raw - Sessions'!$K$5:$K$292,"BARBOURVILLE / CITY HALL",'Raw - Sessions'!$D$5:$D$292) -> 38.907952 | D16: =SUM('Raw - Sessions'!$E$5:$E$292)/SUM('Raw - Sessions'!$D$5:$D$292) -> 29.183252
A17: Revenue ($) | B17: =SUMIF('Raw - Sessions'!$K$5:$K$292,"BARBOURVILLE / TOURISM",'Raw - Sessions'!$P$5:$P$292) -> 458.21 | C17: =SUMIF('Raw - Sessions'!$K$5:$K$292,"BARBOURVILLE / CITY HALL",'Raw - Sessions'!$P$5:$P$292) -> 3577.91 | D17: =SUM('Raw - Sessions'!$P$5:$P$292) -> 4036.12
A18: Avg Session Length (min) | B18: =AVERAGEIFS('Raw - Sessions'!$D$5:$D$292,'Raw - Sessions'!$K$5:$K$292,"BARBOURVILLE / TOURISM")*60 -> 77.539116 | C18: =AVERAGEIFS('Raw - Sessions'!$D$5:$D$292,'Raw - Sessions'!$K$5:$K$292,"BARBOURVILLE / CITY HALL")*60 -> 37.58145 | D18: =AVERAGE('Raw - Sessions'!$D$5:$D$292)*60 -> 44.379803
A19: Max Power (kW) | B19: =SUMPRODUCT(MAX(('Raw - Sessions'!$K$5:$K$292="BARBOURVILLE / TOURISM")*'Raw - Sessions'!F5:F292)) -> 7.4007 | C19: =SUMPRODUCT(MAX(('Raw - Sessions'!$K$5:$K$292="BARBOURVILLE / CITY HALL")*'Raw - Sessions'!F5:F292)) -> 62.882 | D19: =MAX('Raw - Sessions'!F5:F292) -> 62.882
A21: Why this matters for a new Level 2 charger: Tourism (L2) sessions run almost twice as long as City Hall (L3) sessions on average, and cap out near 7.4 kW - it draws fewer visits but holds drivers downtown longer per visit, which is the profile that benefits nearby shops and restaurants most. See the Tourism (Level 2) tab for the full breakdown.

Sheet Tourism (Level 2)
A1: BARBOURVILLE / TOURISM — Level 2 Charger Snapshot
A2: All figures below are filtered to this station only, pulled live from Raw - Sessions (Station = "BARBOURVILLE / TOURISM").
A3: Note on the >10 kW "car load" threshold: this Level 2 charger tops out at about 7.4 kW, so it can never register a session above 10 kW - the combined-workbook threshold (built for the Level 3 charger) does not apply here. The KPI below instead uses a Level-2-appropriate 3 kW threshold to separate active charging from trickle/near-idle time.
A5: Sessions | C5: Total Energy (kWh) | E5: Total Gross Revenue | G5: Avg Session Length (min) | I5: % Sessions Peak Power > 3 kW
A6: =COUNTIF('Raw - Sessions'!$K$5:$K$292,"BARBOURVILLE / TOURISM") -> 49 | C6: =SUMIF('Raw - Sessions'!$K$5:$K$292,"BARBOURVILLE / TOURISM",'Raw - Sessions'!$E$5:$E$292) -> 392.20674 | E6: =SUMIF('Raw - Sessions'!$K$5:$K$292,"BARBOURVILLE / TOURISM",'Raw - Sessions'!$P$5:$P$292) -> 458.21 | G6: =AVERAGEIFS('Raw - Sessions'!$D$5:$D$292,'Raw - Sessions'!$K$5:$K$292,"BARBOURVILLE / TOURISM")*60 -> 77.539116 | I6: =IFERROR(COUNTIFS('Raw - Sessions'!$K$5:$K$292,"BARBOURVILLE / TOURISM",'Raw - Sessions'!$F$5:$F$292,">3")/COUNTIFS('Raw - Sessions'!$K$5:$K$292,"BARBOURVILLE / TOURISM",'Raw - Sessions'!$F$5:$F$292,"<>"),0) -> 0.77777778
A10: By Time of Day
A11: Day Segment | B11: Sessions | C11: Avg Duration (hr) | D11: Total Energy (kWh)
A12: Morning (6-12) | B12: =COUNTIFS('Raw - Sessions'!$K$5:$K$292,"BARBOURVILLE / TOURISM",'Raw - Sessions'!$G$5:$G$292,A12) -> 0 | C12: =IFERROR(AVERAGEIFS('Raw - Sessions'!$D$5:$D$292,'Raw - Sessions'!$K$5:$K$292,"BARBOURVILLE / TOURISM",'Raw - Sessions'!$G$5:$G$292,A12),0) -> 0 | D12: =SUMIFS('Raw - Sessions'!$E$5:$E$292,'Raw - Sessions'!$K$5:$K$292,"BARBOURVILLE / TOURISM",'Raw - Sessions'!$G$5:$G$292,A12) -> 0
A13: Day (12-18) | B13: =COUNTIFS('Raw - Sessions'!$K$5:$K$292,"BARBOURVILLE / TOURISM",'Raw - Sessions'!$G$5:$G$292,A13) -> 17 | C13: =IFERROR(AVERAGEIFS('Raw - Sessions'!$D$5:$D$292,'Raw - Sessions'!$K$5:$K$292,"BARBOURVILLE / TOURISM",'Raw - Sessions'!$G$5:$G$292,A13),0) -> 1.0963399 | D13: =SUMIFS('Raw - Sessions'!$E$5:$E$292,'Raw - Sessions'!$K$5:$K$292,"BARBOURVILLE / TOURISM",'Raw - Sessions'!$G$5:$G$292,A13) -> 130.90719
A14: Evening (18-22) | B14: =COUNTIFS('Raw - Sessions'!$K$5:$K$292,"BARBOURVILLE / TOURISM",'Raw - Sessions'!$G$5:$G$292,A14) -> 15 | C14: =IFERROR(AVERAGEIFS('Raw - Sessions'!$D$5:$D$292,'Raw - Sessions'!$K$5:$K$292,"BARBOURVILLE / TOURISM",'Raw - Sessions'!$G$5:$G$292,A14),0) -> 1.6253519 | D14: =SUMIFS('Raw - Sessions'!$E$5:$E$292,'Raw - Sessions'!$K$5:$K$292,"BARBOURVILLE / TOURISM",'Raw - Sessions'!$G$5:$G$292,A14) -> 142.40364
A15: Night (22-6) | B15: =COUNTIFS('Raw - Sessions'!$K$5:$K$292,"BARBOURVILLE / TOURISM",'Raw - Sessions'!$G$5:$G$292,A15) -> 17 | C15: =IFERROR(AVERAGEIFS('Raw - Sessions'!$D$5:$D$292,'Raw - Sessions'!$K$5:$K$292,"BARBOURVILLE / TOURISM",'Raw - Sessions'!$G$5:$G$292,A15),0) -> 1.1944444 | D15: =SUMIFS('Raw - Sessions'!$E$5:$E$292,'Raw - Sessions'!$K$5:$K$292,"BARBOURVILLE / TOURISM",'Raw - Sessions'!$G$5:$G$292,A15) -> 118.89591
A17: Overnight sessions (started 22:00-6:00) | C17: =COUNTIFS('Raw - Sessions'!$K$5:$K$292,"BARBOURVILLE / TOURISM",'Raw - Sessions'!$I$5:$I$292,TRUE()) -> 17
A20: Monthly Trend
A21: Month | B21: Sessions | C21: Revenue ($) | D21: Energy (kWh)
A22: 45931 | B22: =COUNTIFS('Raw - Sessions'!$K$5:$K$292,"BARBOURVILLE / TOURISM",'Raw - Sessions'!$B$5:$B$292,">="&A22,'Raw - Sessions'!$B$5:$B$292,"<"&DATE(YEAR(A22),MONTH(A22)+1,1)) -> 5 | C22: =SUMIFS('Raw - Sessions'!$P$5:$P$292,'Raw - Sessions'!$K$5:$K$292,"BARBOURVILLE / TOURISM",'Raw - Sessions'!$B$5:$B$292,">="&A22,'Raw - Sessions'!$B$5:$B$292,"<"&DATE(YEAR(A22),MONTH(A22)+1,1)) -> 5.8 | D22: =SUMIFS('Raw - Sessions'!$E$5:$E$292,'Raw - Sessions'!$K$5:$K$292,"BARBOURVILLE / TOURISM",'Raw - Sessions'!$B$5:$B$292,">="&A22,'Raw - Sessions'!$B$5:$B$292,"<"&DATE(YEAR(A22),MONTH(A22)+1,1)) -> 21.88127
A23: 45962 | B23: =COUNTIFS('Raw - Sessions'!$K$5:$K$292,"BARBOURVILLE / TOURISM",'Raw - Sessions'!$B$5:$B$292,">="&A23,'Raw - Sessions'!$B$5:$B$292,"<"&DATE(YEAR(A23),MONTH(A23)+1,1)) -> 5 | C23: =SUMIFS('Raw - Sessions'!$P$5:$P$292,'Raw - Sessions'!$K$5:$K$292,"BARBOURVILLE / TOURISM",'Raw - Sessions'!$B$5:$B$292,">="&A23,'Raw - Sessions'!$B$5:$B$292,"<"&DATE(YEAR(A23),MONTH(A23)+1,1)) -> 7.28 | D23: =SUMIFS('Raw - Sessions'!$E$5:$E$292,'Raw - Sessions'!$K$5:$K$292,"BARBOURVILLE / TOURISM",'Raw - Sessions'!$B$5:$B$292,">="&A23,'Raw - Sessions'!$B$5:$B$292,"<"&DATE(YEAR(A23),MONTH(A23)+1,1)) -> 7.177646
A24: 45992 | B24: =COUNTIFS('Raw - Sessions'!$K$5:$K$292,"BARBOURVILLE / TOURISM",'Raw - Sessions'!$B$5:$B$292,">="&A24,'Raw - Sessions'!$B$5:$B$292,"<"&DATE(YEAR(A24),MONTH(A24)+1,1)) -> 7 | C24: =SUMIFS('Raw - Sessions'!$P$5:$P$292,'Raw - Sessions'!$K$5:$K$292,"BARBOURVILLE / TOURISM",'Raw - Sessions'!$B$5:$B$292,">="&A24,'Raw - Sessions'!$B$5:$B$292,"<"&DATE(YEAR(A24),MONTH(A24)+1,1)) -> 152.82 | D24: =SUMIFS('Raw - Sessions'!$E$5:$E$292,'Raw - Sessions'!$K$5:$K$292,"BARBOURVILLE / TOURISM",'Raw - Sessions'!$B$5:$B$292,">="&A24,'Raw - Sessions'!$B$5:$B$292,"<"&DATE(YEAR(A24),MONTH(A24)+1,1)) -> 151.48866
A25: 46023 | B25: =COUNTIFS('Raw - Sessions'!$K$5:$K$292,"BARBOURVILLE / TOURISM",'Raw - Sessions'!$B$5:$B$292,">="&A25,'Raw - Sessions'!$B$5:$B$292,"<"&DATE(YEAR(A25),MONTH(A25)+1,1)) -> 0 | C25: =SUMIFS('Raw - Sessions'!$P$5:$P$292,'Raw - Sessions'!$K$5:$K$292,"BARBOURVILLE / TOURISM",'Raw - Sessions'!$B$5:$B$292,">="&A25,'Raw - Sessions'!$B$5:$B$292,"<"&DATE(YEAR(A25),MONTH(A25)+1,1)) -> 0 | D25: =SUMIFS('Raw - Sessions'!$E$5:$E$292,'Raw - Sessions'!$K$5:$K$292,"BARBOURVILLE / TOURISM",'Raw - Sessions'!$B$5:$B$292,">="&A25,'Raw - Sessions'!$B$5:$B$292,"<"&DATE(YEAR(A25),MONTH(A25)+1,1)) -> 0
A26: 46054 | B26: =COUNTIFS('Raw - Sessions'!$K$5:$K$292,"BARBOURVILLE / TOURISM",'Raw - Sessions'!$B$5:$B$292,">="&A26,'Raw - Sessions'!$B$5:$B$292,"<"&DATE(YEAR(A26),MONTH(A26)+1,1)) -> 3 | C26: =SUMIFS('Raw - Sessions'!$P$5:$P$292,'Raw - Sessions'!$K$5:$K$292,"BARBOURVILLE / TOURISM",'Raw - Sessions'!$B$5:$B$292,">="&A26,'Raw - Sessions'!$B$5:$B$292,"<"&DATE(YEAR(A26),MONTH(A26)+1,1)) -> 35.46 | D26: =SUMIFS('Raw - Sessions'!$E$5:$E$292,'Raw - Sessions'!$K$5:$K$292,"BARBOURVILLE / TOURISM",'Raw - Sessions'!$B$5:$B$292,">="&A26,'Raw - Sessions'!$B$5:$B$292,"<"&DATE(YEAR(A26),MONTH(A26)+1,1)) -> 22.638451
A27: 46082 | B27: =COUNTIFS('Raw - Sessions'!$K$5:$K$292,"BARBOURVILLE / TOURISM",'Raw - Sessions'!$B$5:$B$292,">="&A27,'Raw - Sessions'!$B$5:$B$292,"<"&DATE(YEAR(A27),MONTH(A27)+1,1)) -> 3 | C27: =SUMIFS('Raw - Sessions'!$P$5:$P$292,'Raw - Sessions'!$K$5:$K$292,"BARBOURVILLE / TOURISM",'Raw - Sessions'!$B$5:$B$292,">="&A27,'Raw - Sessions'!$B$5:$B$292,"<"&DATE(YEAR(A27),MONTH(A27)+1,1)) -> 52.15 | D27: =SUMIFS('Raw - Sessions'!$E$5:$E$292,'Raw - Sessions'!$K$5:$K$292,"BARBOURVILLE / TOURISM",'Raw - Sessions'!$B$5:$B$292,">="&A27,'Raw - Sessions'!$B$5:$B$292,"<"&DATE(YEAR(A27),MONTH(A27)+1,1)) -> 41.212752
A28: 46113 | B28: =COUNTIFS('Raw - Sessions'!$K$5:$K$292,"BARBOURVILLE / TOURISM",'Raw - Sessions'!$B$5:$B$292,">="&A28,'Raw - Sessions'!$B$5:$B$292,"<"&DATE(YEAR(A28),MONTH(A28)+1,1)) -> 10 | C28: =SUMIFS('Raw - Sessions'!$P$5:$P$292,'Raw - Sessions'!$K$5:$K$292,"BARBOURVILLE / TOURISM",'Raw - Sessions'!$B$5:$B$292,">="&A28,'Raw - Sessions'!$B$5:$B$292,"<"&DATE(YEAR(A28),MONTH(A28)+1,1)) -> 88.35 | D28: =SUMIFS('Raw - Sessions'!$E$5:$E$292,'Raw - Sessions'!$K$5:$K$292,"BARBOURVILLE / TOURISM",'Raw - Sessions'!$B$5:$B$292,">="&A28,'Raw - Sessions'!$B$5:$B$292,"<"&DATE(YEAR(A28),MONTH(A28)+1,1)) -> 69.705949
A29: 46143 | B29: =COUNTIFS('Raw - Sessions'!$K$5:$K$292,"BARBOURVILLE / TOURISM",'Raw - Sessions'!$B$5:$B$292,">="&A29,'Raw - Sessions'!$B$5:$B$292,"<"&DATE(YEAR(A29),MONTH(A29)+1,1)) -> 9 | C29: =SUMIFS('Raw - Sessions'!$P$5:$P$292,'Raw - Sessions'!$K$5:$K$292,"BARBOURVILLE / TOURISM",'Raw - Sessions'!$B$5:$B$292,">="&A29,'Raw - Sessions'!$B$5:$B$292,"<"&DATE(YEAR(A29),MONTH(A29)+1,1)) -> 68.98 | D29: =SUMIFS('Raw - Sessions'!$E$5:$E$292,'Raw - Sessions'!$K$5:$K$292,"BARBOURVILLE / TOURISM",'Raw - Sessions'!$B$5:$B$292,">="&A29,'Raw - Sessions'!$B$5:$B$292,"<"&DATE(YEAR(A29),MONTH(A29)+1,1)) -> 52.069591
A30: 46174 | B30: =COUNTIFS('Raw - Sessions'!$K$5:$K$292,"BARBOURVILLE / TOURISM",'Raw - Sessions'!$B$5:$B$292,">="&A30,'Raw - Sessions'!$B$5:$B$292,"<"&DATE(YEAR(A30),MONTH(A30)+1,1)) -> 6 | C30: =SUMIFS('Raw - Sessions'!$P$5:$P$292,'Raw - Sessions'!$K$5:$K$292,"BARBOURVILLE / TOURISM",'Raw - Sessions'!$B$5:$B$292,">="&A30,'Raw - Sessions'!$B$5:$B$292,"<"&DATE(YEAR(A30),MONTH(A30)+1,1)) -> 20.67 | D30: =SUMIFS('Raw - Sessions'!$E$5:$E$292,'Raw - Sessions'!$K$5:$K$292,"BARBOURVILLE / TOURISM",'Raw - Sessions'!$B$5:$B$292,">="&A30,'Raw - Sessions'!$B$5:$B$292,"<"&DATE(YEAR(A30),MONTH(A30)+1,1)) -> 13.727628
A31: 46204 | B31: =COUNTIFS('Raw - Sessions'!$K$5:$K$292,"BARBOURVILLE / TOURISM",'Raw - Sessions'!$B$5:$B$292,">="&A31,'Raw - Sessions'!$B$5:$B$292,"<"&DATE(YEAR(A31),MONTH(A31)+1,1)) -> 1 | C31: =SUMIFS('Raw - Sessions'!$P$5:$P$292,'Raw - Sessions'!$K$5:$K$292,"BARBOURVILLE / TOURISM",'Raw - Sessions'!$B$5:$B$292,">="&A31,'Raw - Sessions'!$B$5:$B$292,"<"&DATE(YEAR(A31),MONTH(A31)+1,1)) -> 26.7 | D31: =SUMIFS('Raw - Sessions'!$E$5:$E$292,'Raw - Sessions'!$K$5:$K$292,"BARBOURVILLE / TOURISM",'Raw - Sessions'!$B$5:$B$292,">="&A31,'Raw - Sessions'!$B$5:$B$292,"<"&DATE(YEAR(A31),MONTH(A31)+1,1)) -> 12.304789
A34: Top States of Origin (sessions with known ZIP)
A35: Est. State | B35: Sessions
A36: ='Visitor Origin'!A5 -> KY | B36: =COUNTIFS('Raw - Sessions'!$K$5:$K$292,"BARBOURVILLE / TOURISM",'Raw - Sessions'!$O$5:$O$292,A36) -> 7
A37: ='Visitor Origin'!A6 -> TN | B37: =COUNTIFS('Raw - Sessions'!$K$5:$K$292,"BARBOURVILLE / TOURISM",'Raw - Sessions'!$O$5:$O$292,A37) -> 1
A38: ='Visitor Origin'!A7 -> OH | B38: =COUNTIFS('Raw - Sessions'!$K$5:$K$292,"BARBOURVILLE / TOURISM",'Raw - Sessions'!$O$5:$O$292,A38) -> 1
A39: ='Visitor Origin'!A8 -> NC | B39: =COUNTIFS('Raw - Sessions'!$K$5:$K$292,"BARBOURVILLE / TOURISM",'Raw - Sessions'!$O$5:$O$292,A39) -> 0
A40: ='Visitor Origin'!A9 -> IL | B40: =COUNTIFS('Raw - Sessions'!$K$5:$K$292,"BARBOURVILLE / TOURISM",'Raw - Sessions'!$O$5:$O$292,A40) -> 4
A41: ='Visitor Origin'!A10 -> FL | B41: =COUNTIFS('Raw - Sessions'!$K$5:$K$292,"BARBOURVILLE / TOURISM",'Raw - Sessions'!$O$5:$O$292,A41) -> 0
A42: ='Visitor Origin'!A11 -> SC | B42: =COUNTIFS('Raw - Sessions'!$K$5:$K$292,"BARBOURVILLE / TOURISM",'Raw - Sessions'!$O$5:$O$292,A42) -> 0
A43: ='Visitor Origin'!A12 -> MI | B43: =COUNTIFS('Raw - Sessions'!$K$5:$K$292,"BARBOURVILLE / TOURISM",'Raw - Sessions'!$O$5:$O$292,A43) -> 0
A44: ='Visitor Origin'!A13 -> WI | B44: =COUNTIFS('Raw - Sessions'!$K$5:$K$292,"BARBOURVILLE / TOURISM",'Raw - Sessions'!$O$5:$O$292,A44) -> 0
A45: ='Visitor Origin'!A14 -> IN | B45: =COUNTIFS('Raw - Sessions'!$K$5:$K$292,"BARBOURVILLE / TOURISM",'Raw - Sessions'!$O$5:$O$292,A45) -> 0
A46: ='Visitor Origin'!A15 -> GA | B46: =COUNTIFS('Raw - Sessions'!$K$5:$K$292,"BARBOURVILLE / TOURISM",'Raw - Sessions'!$O$5:$O$292,A46) -> 0
A47: ='Visitor Origin'!A16 -> TX | B47: =COUNTIFS('Raw - Sessions'!$K$5:$K$292,"BARBOURVILLE / TOURISM",'Raw - Sessions'!$O$5:$O$292,A47) -> 0
... A54: ='Visitor Origin'!A23 -> OK | B54: =COUNTIFS('Raw - Sessions'!$K$5:$K$292,"BARBOURVILLE / TOURISM",'Raw - Sessions'!$O$5:$O$292,A54) -> 0
A56: States with 0 sessions for this charger are still listed for consistency with the combined Visitor Origin tab.

Sheet City Hall (Level 3)
A1: BARBOURVILLE / CITY HALL — Level 3 (DCFC) Charger Snapshot
A2: All figures below are filtered to this station only, pulled live from Raw - Sessions (Station = "BARBOURVILLE / CITY HALL").
A5: Sessions | C5: Total Energy (kWh) | E5: Total Gross Revenue | G5: Avg Session Length (min) | I5: % Sessions Peak Power > 10 kW
A6: =COUNTIF('Raw - Sessions'!$K$5:$K$292,"BARBOURVILLE / CITY HALL") -> 239 | C6: =SUMIF('Raw - Sessions'!$K$5:$K$292,"BARBOURVILLE / CITY HALL",'Raw - Sessions'!$E$5:$E$292) -> 5824.4988 | E6: =SUMIF('Raw - Sessions'!$K$5:$K$292,"BARBOURVILLE / CITY HALL",'Raw - Sessions'!$P$5:$P$292) -> 3577.91 | G6: =AVERAGEIFS('Raw - Sessions'!$D$5:$D$292,'Raw - Sessions'!$K$5:$K$292,"BARBOURVILLE / CITY HALL")*60 -> 37.58145 | I6: =IFERROR(COUNTIFS('Raw - Sessions'!$K$5:$K$292,"BARBOURVILLE / CITY HALL",'Raw - Sessions'!$F$5:$F$292,">10")/COUNTIFS('Raw - Sessions'!$K$5:$K$292,"BARBOURVILLE / CITY HALL",'Raw - Sessions'!$F$5:$F$292,"<>"),0) -> 0.78540773
A10: By Time of Day
A11: Day Segment | B11: Sessions | C11: Avg Duration (hr) | D11: Total Energy (kWh)
A12: Morning (6-12) | B12: =COUNTIFS('Raw - Sessions'!$K$5:$K$292,"BARBOURVILLE / CITY HALL",'Raw - Sessions'!$G$5:$G$292,A12) -> 4 | C12: =IFERROR(AVERAGEIFS('Raw - Sessions'!$D$5:$D$292,'Raw - Sessions'!$K$5:$K$292,"BARBOURVILLE / CITY HALL",'Raw - Sessions'!$G$5:$G$292,A12),0) -> 0.54180556 | D12: =SUMIFS('Raw - Sessions'!$E$5:$E$292,'Raw - Sessions'!$K$5:$K$292,"BARBOURVILLE / CITY HALL",'Raw - Sessions'!$G$5:$G$292,A12) -> 57.8262
A13: Day (12-18) | B13: =COUNTIFS('Raw - Sessions'!$K$5:$K$292,"BARBOURVILLE / CITY HALL",'Raw - Sessions'!$G$5:$G$292,A13) -> 79 | C13: =IFERROR(AVERAGEIFS('Raw - Sessions'!$D$5:$D$292,'Raw - Sessions'!$K$5:$K$292,"BARBOURVILLE / CITY HALL",'Raw - Sessions'!$G$5:$G$292,A13),0) -> 0.64993671 | D13: =SUMIFS('Raw - Sessions'!$E$5:$E$292,'Raw - Sessions'!$K$5:$K$292,"BARBOURVILLE / CITY HALL",'Raw - Sessions'!$G$5:$G$292,A13) -> 2101.0725
A14: Evening (18-22) | B14: =COUNTIFS('Raw - Sessions'!$K$5:$K$292,"BARBOURVILLE / CITY HALL",'Raw - Sessions'!$G$5:$G$292,A14) -> 87 | C14: =IFERROR(AVERAGEIFS('Raw - Sessions'!$D$5:$D$292,'Raw - Sessions'!$K$5:$K$292,"BARBOURVILLE / CITY HALL",'Raw - Sessions'!$G$5:$G$292,A14),0) -> 0.6467401 | D14: =SUMIFS('Raw - Sessions'!$E$5:$E$292,'Raw - Sessions'!$K$5:$K$292,"BARBOURVILLE / CITY HALL",'Raw - Sessions'!$G$5:$G$292,A14) -> 2123.8601
A15: Night (22-6) | B15: =COUNTIFS('Raw - Sessions'!$K$5:$K$292,"BARBOURVILLE / CITY HALL",'Raw - Sessions'!$G$5:$G$292,A15) -> 69 | C15: =IFERROR(AVERAGEIFS('Raw - Sessions'!$D$5:$D$292,'Raw - Sessions'!$K$5:$K$292,"BARBOURVILLE / CITY HALL",'Raw - Sessions'!$G$5:$G$292,A15),0) -> 0.5785628 | D15: =SUMIFS('Raw - Sessions'!$E$5:$E$292,'Raw - Sessions'!$K$5:$K$292,"BARBOURVILLE / CITY HALL",'Raw - Sessions'!$G$5:$G$292,A15) -> 1541.74
A17: Overnight sessions (started 22:00-6:00) | C17: =COUNTIFS('Raw - Sessions'!$K$5:$K$292,"BARBOURVILLE / CITY HALL",'Raw - Sessions'!$I$5:$I$292,TRUE()) -> 69
A20: Monthly Trend
A21: Month | B21: Sessions | C21: Revenue ($) | D21: Energy (kWh)
A22: 45931 | B22: =COUNTIFS('Raw - Sessions'!$K$5:$K$292,"BARBOURVILLE / CITY HALL",'Raw - Sessions'!$B$5:$B$292,">="&A22,'Raw - Sessions'!$B$5:$B$292,"<"&DATE(YEAR(A22),MONTH(A22)+1,1)) -> 22 | C22: =SUMIFS('Raw - Sessions'!$P$5:$P$292,'Raw - Sessions'!$K$5:$K$292,"BARBOURVILLE / CITY HALL",'Raw - Sessions'!$B$5:$B$292,">="&A22,'Raw - Sessions'!$B$5:$B$292,"<"&DATE(YEAR(A22),MONTH(A22)+1,1)) -> 182.76 | D22: =SUMIFS('Raw - Sessions'!$E$5:$E$292,'Raw - Sessions'!$K$5:$K$292,"BARBOURVILLE / CITY HALL",'Raw - Sessions'!$B$5:$B$292,">="&A22,'Raw - Sessions'!$B$5:$B$292,"<"&DATE(YEAR(A22),MONTH(A22)+1,1)) -> 385.2387
A23: 45962 | B23: =COUNTIFS('Raw - Sessions'!$K$5:$K$292,"BARBOURVILLE / CITY HALL",'Raw - Sessions'!$B$5:$B$292,">="&A23,'Raw - Sessions'!$B$5:$B$292,"<"&DATE(YEAR(A23),MONTH(A23)+1,1)) -> 24 | C23: =SUMIFS('Raw - Sessions'!$P$5:$P$292,'Raw - Sessions'!$K$5:$K$292,"BARBOURVILLE / CITY HALL",'Raw - Sessions'!$B$5:$B$292,">="&A23,'Raw - Sessions'!$B$5:$B$292,"<"&DATE(YEAR(A23),MONTH(A23)+1,1)) -> 394.07 | D23: =SUMIFS('Raw - Sessions'!$E$5:$E$292,'Raw - Sessions'!$K$5:$K$292,"BARBOURVILLE / CITY HALL",'Raw - Sessions'!$B$5:$B$292,">="&A23,'Raw - Sessions'!$B$5:$B$292,"<"&DATE(YEAR(A23),MONTH(A23)+1,1)) -> 775.995
A24: 45992 | B24: =COUNTIFS('Raw - Sessions'!$K$5:$K$292,"BARBOURVILLE / CITY HALL",'Raw - Sessions'!$B$5:$B$292,">="&A24,'Raw - Sessions'!$B$5:$B$292,"<"&DATE(YEAR(A24),MONTH(A24)+1,1)) -> 26 | C24: =SUMIFS('Raw - Sessions'!$P$5:$P$292,'Raw - Sessions'!$K$5:$K$292,"BARBOURVILLE / CITY HALL",'Raw - Sessions'!$B$5:$B$292,">="&A24,'Raw - Sessions'!$B$5:$B$292,"<"&DATE(YEAR(A24),MONTH(A24)+1,1)) -> 326.83 | D24: =SUMIFS('Raw - Sessions'!$E$5:$E$292,'Raw - Sessions'!$K$5:$K$292,"BARBOURVILLE / CITY HALL",'Raw - Sessions'!$B$5:$B$292,">="&A24,'Raw - Sessions'!$B$5:$B$292,"<"&DATE(YEAR(A24),MONTH(A24)+1,1)) -> 612.6473
A25: 46023 | B25: =COUNTIFS('Raw - Sessions'!$K$5:$K$292,"BARBOURVILLE / CITY HALL",'Raw - Sessions'!$B$5:$B$292,">="&A25,'Raw - Sessions'!$B$5:$B$292,"<"&DATE(YEAR(A25),MONTH(A25)+1,1)) -> 11 | C25: =SUMIFS('Raw - Sessions'!$P$5:$P$292,'Raw - Sessions'!$K$5:$K$292,"BARBOURVILLE / CITY HALL",'Raw - Sessions'!$B$5:$B$292,">="&A25,'Raw - Sessions'!$B$5:$B$292,"<"&DATE(YEAR(A25),MONTH(A25)+1,1)) -> 50.49 | D25: =SUMIFS('Raw - Sessions'!$E$5:$E$292,'Raw - Sessions'!$K$5:$K$292,"BARBOURVILLE / CITY HALL",'Raw - Sessions'!$B$5:$B$292,">="&A25,'Raw - Sessions'!$B$5:$B$292,"<"&DATE(YEAR(A25),MONTH(A25)+1,1)) -> 98.330102
A26: 46054 | B26: =COUNTIFS('Raw - Sessions'!$K$5:$K$292,"BARBOURVILLE / CITY HALL",'Raw - Sessions'!$B$5:$B$292,">="&A26,'Raw - Sessions'!$B$5:$B$292,"<"&DATE(YEAR(A26),MONTH(A26)+1,1)) -> 24 | C26: =SUMIFS('Raw - Sessions'!$P$5:$P$292,'Raw - Sessions'!$K$5:$K$292,"BARBOURVILLE / CITY HALL",'Raw - Sessions'!$B$5:$B$292,">="&A26,'Raw - Sessions'!$B$5:$B$292,"<"&DATE(YEAR(A26),MONTH(A26)+1,1)) -> 467.93 | D26: =SUMIFS('Raw - Sessions'!$E$5:$E$292,'Raw - Sessions'!$K$5:$K$292,"BARBOURVILLE / CITY HALL",'Raw - Sessions'!$B$5:$B$292,">="&A26,'Raw - Sessions'!$B$5:$B$292,"<"&DATE(YEAR(A26),MONTH(A26)+1,1)) -> 784.6669
A27: 46082 | B27: =COUNTIFS('Raw - Sessions'!$K$5:$K$292,"BARBOURVILLE / CITY HALL",'Raw - Sessions'!$B$5:$B$292,">="&A27,'Raw - Sessions'!$B$5:$B$292,"<"&DATE(YEAR(A27),MONTH(A27)+1,1)) -> 18 | C27: =SUMIFS('Raw - Sessions'!$P$5:$P$292,'Raw - Sessions'!$K$5:$K$292,"BARBOURVILLE / CITY HALL",'Raw - Sessions'!$B$5:$B$292,">="&A27,'Raw - Sessions'!$B$5:$B$292,"<"&DATE(YEAR(A27),MONTH(A27)+1,1)) -> 410.2 | D27: =SUMIFS('Raw - Sessions'!$E$5:$E$292,'Raw - Sessions'!$K$5:$K$292,"BARBOURVILLE / CITY HALL",'Raw - Sessions'!$B$5:$B$292,">="&A27,'Raw - Sessions'!$B$5:$B$292,"<"&DATE(YEAR(A27),MONTH(A27)+1,1)) -> 613.9706
A28: 46113 | B28: =COUNTIFS('Raw - Sessions'!$K$5:$K$292,"BARBOURVILLE / CITY HALL",'Raw - Sessions'!$B$5:$B$292,">="&A28,'Raw - Sessions'!$B$5:$B$292,"<"&DATE(YEAR(A28),MONTH(A28)+1,1)) -> 37 | C28: =SUMIFS('Raw - Sessions'!$P$5:$P$292,'Raw - Sessions'!$K$5:$K$292,"BARBOURVILLE / CITY HALL",'Raw - Sessions'!$B$5:$B$292,">="&A28,'Raw - Sessions'!$B$5:$B$292,"<"&DATE(YEAR(A28),MONTH(A28)+1,1)) -> 736.86 | D28: =SUMIFS('Raw - Sessions'!$E$5:$E$292,'Raw - Sessions'!$K$5:$K$292,"BARBOURVILLE / CITY HALL",'Raw - Sessions'!$B$5:$B$292,">="&A28,'Raw - Sessions'!$B$5:$B$292,"<"&DATE(YEAR(A28),MONTH(A28)+1,1)) -> 1125.8821
A29: 46143 | B29: =COUNTIFS('Raw - Sessions'!$K$5:$K$292,"BARBOURVILLE / CITY HALL",'Raw - Sessions'!$B$5:$B$292,">="&A29,'Raw - Sessions'!$B$5:$B$292,"<"&DATE(YEAR(A29),MONTH(A29)+1,1)) -> 31 | C29: =SUMIFS('Raw - Sessions'!$P$5:$P$292,'Raw - Sessions'!$K$5:$K$292,"BARBOURVILLE / CITY HALL",'Raw - Sessions'!$B$5:$B$292,">="&A29,'Raw - Sessions'!$B$5:$B$292,"<"&DATE(YEAR(A29),MONTH(A29)+1,1)) -> 537.16 | D29: =SUMIFS('Raw - Sessions'!$E$5:$E$292,'Raw - Sessions'!$K$5:$K$292,"BARBOURVILLE / CITY HALL",'Raw - Sessions'!$B$5:$B$292,">="&A29,'Raw - Sessions'!$B$5:$B$292,"<"&DATE(YEAR(A29),MONTH(A29)+1,1)) -> 766.1055
A30: 46174 | B30: =COUNTIFS('Raw - Sessions'!$K$5:$K$292,"BARBOURVILLE / CITY HALL",'Raw - Sessions'!$B$5:$B$292,">="&A30,'Raw - Sessions'!$B$5:$B$292,"<"&DATE(YEAR(A30),MONTH(A30)+1,1)) -> 40 | C30: =SUMIFS('Raw - Sessions'!$P$5:$P$292,'Raw - Sessions'!$K$5:$K$292,"BARBOURVILLE / CITY HALL",'Raw - Sessions'!$B$5:$B$292,">="&A30,'Raw - Sessions'!$B$5:$B$292,"<"&DATE(YEAR(A30),MONTH(A30)+1,1)) -> 405.05 | D30: =SUMIFS('Raw - Sessions'!$E$5:$E$292,'Raw - Sessions'!$K$5:$K$292,"BARBOURVILLE / CITY HALL",'Raw - Sessions'!$B$5:$B$292,">="&A30,'Raw - Sessions'!$B$5:$B$292,"<"&DATE(YEAR(A30),MONTH(A30)+1,1)) -> 568.0701
A31: 46204 | B31: =COUNTIFS('Raw - Sessions'!$K$5:$K$292,"BARBOURVILLE / CITY HALL",'Raw - Sessions'!$B$5:$B$292,">="&A31,'Raw - Sessions'!$B$5:$B$292,"<"&DATE(YEAR(A31),MONTH(A31)+1,1)) -> 6 | C31: =SUMIFS('Raw - Sessions'!$P$5:$P$292,'Raw - Sessions'!$K$5:$K$292,"BARBOURVILLE / CITY HALL",'Raw - Sessions'!$B$5:$B$292,">="&A31,'Raw - Sessions'!$B$5:$B$292,"<"&DATE(YEAR(A31),MONTH(A31)+1,1)) -> 66.56 | D31: =SUMIFS('Raw - Sessions'!$E$5:$E$292,'Raw - Sessions'!$K$5:$K$292,"BARBOURVILLE / CITY HALL",'Raw - Sessions'!$B$5:$B$292,">="&A31,'Raw - Sessions'!$B$5:$B$292,"<"&DATE(YEAR(A31),MONTH(A31)+1,1)) -> 93.5925
A34: Top States of Origin (sessions with known ZIP)
A35: Est. State | B35: Sessions
A36: ='Visitor Origin'!A5 -> KY | B36: =COUNTIFS('Raw - Sessions'!$K$5:$K$292,"BARBOURVILLE / CITY HALL",'Raw - Sessions'!$O$5:$O$292,A36) -> 89
A37: ='Visitor Origin'!A6 -> TN | B37: =COUNTIFS('Raw - Sessions'!$K$5:$K$292,"BARBOURVILLE / CITY HALL",'Raw - Sessions'!$O$5:$O$292,A37) -> 17
A38: ='Visitor Origin'!A7 -> OH | B38: =COUNTIFS('Raw - Sessions'!$K$5:$K$292,"BARBOURVILLE / CITY HALL",'Raw - Sessions'!$O$5:$O$292,A38) -> 9
A39: ='Visitor Origin'!A8 -> NC | B39: =COUNTIFS('Raw - Sessions'!$K$5:$K$292,"BARBOURVILLE / CITY HALL",'Raw - Sessions'!$O$5:$O$292,A39) -> 9
A40: ='Visitor Origin'!A9 -> IL | B40: =COUNTIFS('Raw - Sessions'!$K$5:$K$292,"BARBOURVILLE / CITY HALL",'Raw - Sessions'!$O$5:$O$292,A40) -> 1
A41: ='Visitor Origin'!A10 -> FL | B41: =COUNTIFS('Raw - Sessions'!$K$5:$K$292,"BARBOURVILLE / CITY HALL",'Raw - Sessions'!$O$5:$O$292,A41) -> 3
A42: ='Visitor Origin'!A11 -> SC | B42: =COUNTIFS('Raw - Sessions'!$K$5:$K$292,"BARBOURVILLE / CITY HALL",'Raw - Sessions'!$O$5:$O$292,A42) -> 3
A43: ='Visitor Origin'!A12 -> MI | B43: =COUNTIFS('Raw - Sessions'!$K$5:$K$292,"BARBOURVILLE / CITY HALL",'Raw - Sessions'!$O$5:$O$292,A43) -> 3
A44: ='Visitor Origin'!A13 -> WI | B44: =COUNTIFS('Raw - Sessions'!$K$5:$K$292,"BARBOURVILLE / CITY HALL",'Raw - Sessions'!$O$5:$O$292,A44) -> 3
A45: ='Visitor Origin'!A14 -> IN | B45: =COUNTIFS('Raw - Sessions'!$K$5:$K$292,"BARBOURVILLE / CITY HALL",'Raw - Sessions'!$O$5:$O$292,A45) -> 2
A46: ='Visitor Origin'!A15 -> GA | B46: =COUNTIFS('Raw - Sessions'!$K$5:$K$292,"BARBOURVILLE / CITY HALL",'Raw - Sessions'!$O$5:$O$292,A46) -> 2
A47: ='Visitor Origin'!A16 -> TX | B47: =COUNTIFS('Raw - Sessions'!$K$5:$K$292,"BARBOURVILLE / CITY HALL",'Raw - Sessions'!$O$5:$O$292,A47) -> 2
... A54: ='Visitor Origin'!A23 -> OK | B54: =COUNTIFS('Raw - Sessions'!$K$5:$K$292,"BARBOURVILLE / CITY HALL",'Raw - Sessions'!$O$5:$O$292,A54) -> 1
A56: States with 0 sessions for this charger are still listed for consistency with the combined Visitor Origin tab.

Sheet Daily Summary
A1: Daily Charging Activity Summary (All Stations Combined)
A2: One row per calendar day across the full 12-month export. Sessions/duration/energy pull live from Raw - Sessions; Charger Energy pulls live from Raw - Daily Energy.
A4: Total Sessions | C4: Days in Reporting Period | E4: Avg Sessions / Active Day | G4: Avg Charging Hours / Day (full period) | I4: Avg Energy / Day (kWh, full period) | K4: Avg Energy / Active Day (kWh) | M4: Avg Power While Charging (kW) | O4: Rural Benchmark (hrs/day, per requester)
A5: =COUNTA('Raw - Sessions'!A5:A292) -> 288 | C5: ='Raw - Daily Energy'!A369-'Raw - Daily Energy'!A5+1 -> 365 | E5: =SUM(B10:B374)/COUNTIF(B10:B374,">0") -> 2.028169 | G5: =SUM(C10:C374)/(A374-A10+1) -> 0.58362481 | I5: =SUM('Raw - Sessions'!E5:E292)/C5 -> 17.03207 | K5: =SUM('Raw - Sessions'!E5:E292)/SUM('Raw - Sessions'!AF5:AF292) -> 45.048591 | M5: =SUM('Raw - Sessions'!E5:E292)/SUM('Raw - Sessions'!D5:D292) -> 29.183252 | O5: 1.2
A8: Day-by-day detail
A9: Date | B9: Sessions | C9: Total Session Duration (hr) | D9: Total Session Energy (kWh) | E9: Charger Meter Energy (kWh) | F9: Total Revenue ($)
A10: ='Raw - Daily Energy'!A5 -> 45850 | B10: =COUNTIF('Raw - Sessions'!$R$5:$R$292,A10) -> 0 | C10: =SUMIF('Raw - Sessions'!$R$5:$R$292,A10,'Raw - Sessions'!$D$5:$D$292) -> 0 | D10: =SUMIF('Raw - Sessions'!$R$5:$R$292,A10,'Raw - Sessions'!$E$5:$E$292) -> 0 | E10: ='Raw - Daily Energy'!B5 -> 0 | F10: =SUMIF('Raw - Sessions'!$R$5:$R$292,A10,'Raw - Sessions'!$P$5:$P$292) -> 0
A11: ='Raw - Daily Energy'!A6 -> 45851 | B11: =COUNTIF('Raw - Sessions'!$R$5:$R$292,A11) -> 0 | C11: =SUMIF('Raw - Sessions'!$R$5:$R$292,A11,'Raw - Sessions'!$D$5:$D$292) -> 0 | D11: =SUMIF('Raw - Sessions'!$R$5:$R$292,A11,'Raw - Sessions'!$E$5:$E$292) -> 0 | E11: ='Raw - Daily Energy'!B6 -> 0 | F11: =SUMIF('Raw - Sessions'!$R$5:$R$292,A11,'Raw - Sessions'!$P$5:$P$292) -> 0
A12: ='Raw - Daily Energy'!A7 -> 45852 | B12: =COUNTIF('Raw - Sessions'!$R$5:$R$292,A12) -> 0 | C12: =SUMIF('Raw - Sessions'!$R$5:$R$292,A12,'Raw - Sessions'!$D$5:$D$292) -> 0 | D12: =SUMIF('Raw - Sessions'!$R$5:$R$292,A12,'Raw - Sessions'!$E$5:$E$292) -> 0 | E12: ='Raw - Daily Energy'!B7 -> 0 | F12: =SUMIF('Raw - Sessions'!$R$5:$R$292,A12,'Raw - Sessions'!$P$5:$P$292) -> 0
A13: ='Raw - Daily Energy'!A8 -> 45853 | B13: =COUNTIF('Raw - Sessions'!$R$5:$R$292,A13) -> 0 | C13: =SUMIF('Raw - Sessions'!$R$5:$R$292,A13,'Raw - Sessions'!$D$5:$D$292) -> 0 | D13: =SUMIF('Raw - Sessions'!$R$5:$R$292,A13,'Raw - Sessions'!$E$5:$E$292) -> 0 | E13: ='Raw - Daily Energy'!B8 -> 0 | F13: =SUMIF('Raw - Sessions'!$R$5:$R$292,A13,'Raw - Sessions'!$P$5:$P$292) -> 0
A14: ='Raw - Daily Energy'!A9 -> 45854 | B14: =COUNTIF('Raw - Sessions'!$R$5:$R$292,A14) -> 0 | C14: =SUMIF('Raw - Sessions'!$R$5:$R$292,A14,'Raw - Sessions'!$D$5:$D$292) -> 0 | D14: =SUMIF('Raw - Sessions'!$R$5:$R$292,A14,'Raw - Sessions'!$E$5:$E$292) -> 0 | E14: ='Raw - Daily Energy'!B9 -> 0 | F14: =SUMIF('Raw - Sessions'!$R$5:$R$292,A14,'Raw - Sessions'!$P$5:$P$292) -> 0
A15: ='Raw - Daily Energy'!A10 -> 45855 | B15: =COUNTIF('Raw - Sessions'!$R$5:$R$292,A15) -> 0 | C15: =SUMIF('Raw - Sessions'!$R$5:$R$292,A15,'Raw - Sessions'!$D$5:$D$292) -> 0 | D15: =SUMIF('Raw - Sessions'!$R$5:$R$292,A15,'Raw - Sessions'!$E$5:$E$292) -> 0 | E15: ='Raw - Daily Energy'!B10 -> 0 | F15: =SUMIF('Raw - Sessions'!$R$5:$R$292,A15,'Raw - Sessions'!$P$5:$P$292) -> 0
A16: ='Raw - Daily Energy'!A11 -> 45856 | B16: =COUNTIF('Raw - Sessions'!$R$5:$R$292,A16) -> 0 | C16: =SUMIF('Raw - Sessions'!$R$5:$R$292,A16,'Raw - Sessions'!$D$5:$D$292) -> 0 | D16: =SUMIF('Raw - Sessions'!$R$5:$R$292,A16,'Raw - Sessions'!$E$5:$E$292) -> 0 | E16: ='Raw - Daily Energy'!B11 -> 0 | F16: =SUMIF('Raw - Sessions'!$R$5:$R$292,A16,'Raw - Sessions'!$P$5:$P$292) -> 0
A17: ='Raw - Daily Energy'!A12 -> 45857 | B17: =COUNTIF('Raw - Sessions'!$R$5:$R$292,A17) -> 0 | C17: =SUMIF('Raw - Sessions'!$R$5:$R$292,A17,'Raw - Sessions'!$D$5:$D$292) -> 0 | D17: =SUMIF('Raw - Sessions'!$R$5:$R$292,A17,'Raw - Sessions'!$E$5:$E$292) -> 0 | E17: ='Raw - Daily Energy'!B12 -> 0 | F17: =SUMIF('Raw - Sessions'!$R$5:$R$292,A17,'Raw - Sessions'!$P$5:$P$292) -> 0
A18: ='Raw - Daily Energy'!A13 -> 45858 | B18: =COUNTIF('Raw - Sessions'!$R$5:$R$292,A18) -> 0 | C18: =SUMIF('Raw - Sessions'!$R$5:$R$292,A18,'Raw - Sessions'!$D$5:$D$292) -> 0 | D18: =SUMIF('Raw - Sessions'!$R$5:$R$292,A18,'Raw - Sessions'!$E$5:$E$292) -> 0 | E18: ='Raw - Daily Energy'!B13 -> 0 | F18: =SUMIF('Raw - Sessions'!$R$5:$R$292,A18,'Raw - Sessions'!$P$5:$P$292) -> 0
A19: ='Raw - Daily Energy'!A14 -> 45859 | B19: =COUNTIF('Raw - Sessions'!$R$5:$R$292,A19) -> 0 | C19: =SUMIF('Raw - Sessions'!$R$5:$R$292,A19,'Raw - Sessions'!$D$5:$D$292) -> 0 | D19: =SUMIF('Raw - Sessions'!$R$5:$R$292,A19,'Raw - Sessions'!$E$5:$E$292) -> 0 | E19: ='Raw - Daily Energy'!B14 -> 0 | F19: =SUMIF('Raw - Sessions'!$R$5:$R$292,A19,'Raw - Sessions'!$P$5:$P$292) -> 0
A20: ='Raw - Daily Energy'!A15 -> 45860 | B20: =COUNTIF('Raw - Sessions'!$R$5:$R$292,A20) -> 0 | C20: =SUMIF('Raw - Sessions'!$R$5:$R$292,A20,'Raw - Sessions'!$D$5:$D$292) -> 0 | D20: =SUMIF('Raw - Sessions'!$R$5:$R$292,A20,'Raw - Sessions'!$E$5:$E$292) -> 0 | E20: ='Raw - Daily Energy'!B15 -> 0 | F20: =SUMIF('Raw - Sessions'!$R$5:$R$292,A20,'Raw - Sessions'!$P$5:$P$292) -> 0
A21: ='Raw - Daily Energy'!A16 -> 45861 | B21: =COUNTIF('Raw - Sessions'!$R$5:$R$292,A21) -> 0 | C21: =SUMIF('Raw - Sessions'!$R$5:$R$292,A21,'Raw - Sessions'!$D$5:$D$292) -> 0 | D21: =SUMIF('Raw - Sessions'!$R$5:$R$292,A21,'Raw - Sessions'!$E$5:$E$292) -> 0 | E21: ='Raw - Daily Energy'!B16 -> 0 | F21: =SUMIF('Raw - Sessions'!$R$5:$R$292,A21,'Raw - Sessions'!$P$5:$P$292) -> 0
... A374: ='Raw - Daily Energy'!A369 -> 46214 | B374: =COUNTIF('Raw - Sessions'!$R$5:$R$292,A374) -> 0 | C374: =SUMIF('Raw - Sessions'!$R$5:$R$292,A374,'Raw - Sessions'!$D$5:$D$292) -> 0 | D374: =SUMIF('Raw - Sessions'!$R$5:$R$292,A374,'Raw - Sessions'!$E$5:$E$292) -> 0 | E374: ='Raw - Daily Energy'!B369 -> 0 | F374: =SUMIF('Raw - Sessions'!$R$5:$R$292,A374,'Raw - Sessions'!$P$5:$P$292) -> 0

Sheet Time of Day
A1: When People Charge (All Stations Combined): Time-of-Day & Overnight Patterns
A2: Day Segment: Morning 6:00-12:00, Day 12:00-18:00, Evening 18:00-22:00, Night 22:00-6:00 (based on Session Start).
A4: Day Segment | B4: Sessions | C4: % of All Sessions | D4: Avg Duration (hr) | E4: Total Energy (kWh) | F4: Avg % of Session Time >10kW
A5: Morning (6-12) | B5: =COUNTIF('Raw - Sessions'!$G$5:$G$292,A5) -> 4 | C5: =B5/SUM($B$5:$B$8) -> 0.013888889 | D5: =AVERAGEIF('Raw - Sessions'!$G$5:$G$292,A5,'Raw - Sessions'!$D$5:$D$292) -> 0.54180556 | E5: =SUMIF('Raw - Sessions'!$G$5:$G$292,A5,'Raw - Sessions'!$E$5:$E$292) -> 57.8262 | F5: =AVERAGEIF('Raw - Sessions'!$G$5:$G$292,A5,'Raw - Sessions'!$J$5:$J$292) -> 0.92745446
A6: Day (12-18) | B6: =COUNTIF('Raw - Sessions'!$G$5:$G$292,A6) -> 96 | C6: =B6/SUM($B$5:$B$8) -> 0.33333333 | D6: =AVERAGEIF('Raw - Sessions'!$G$5:$G$292,A6,'Raw - Sessions'!$D$5:$D$292) -> 0.72898727 | E6: =SUMIF('Raw - Sessions'!$G$5:$G$292,A6,'Raw - Sessions'!$E$5:$E$292) -> 2231.9797 | F6: =AVERAGEIF('Raw - Sessions'!$G$5:$G$292,A6,'Raw - Sessions'!$J$5:$J$292) -> 0.81222661
A7: Evening (18-22) | B7: =COUNTIF('Raw - Sessions'!$G$5:$G$292,A7) -> 102 | C7: =B7/SUM($B$5:$B$8) -> 0.35416667 | D7: =AVERAGEIF('Raw - Sessions'!$G$5:$G$292,A7,'Raw - Sessions'!$D$5:$D$292) -> 0.79065359 | E7: =SUMIF('Raw - Sessions'!$G$5:$G$292,A7,'Raw - Sessions'!$E$5:$E$292) -> 2266.2637 | F7: =AVERAGEIF('Raw - Sessions'!$G$5:$G$292,A7,'Raw - Sessions'!$J$5:$J$292) -> 0.8383424
A8: Night (22-6) | B8: =COUNTIF('Raw - Sessions'!$G$5:$G$292,A8) -> 86 | C8: =B8/SUM($B$5:$B$8) -> 0.29861111 | D8: =AVERAGEIF('Raw - Sessions'!$G$5:$G$292,A8,'Raw - Sessions'!$D$5:$D$292) -> 0.70030685 | E8: =SUMIF('Raw - Sessions'!$G$5:$G$292,A8,'Raw - Sessions'!$E$5:$E$292) -> 1660.6359 | F8: =AVERAGEIF('Raw - Sessions'!$G$5:$G$292,A8,'Raw - Sessions'!$J$5:$J$292) -> 0.75658178
A28: Overnight Charging Frequency
A29: Overnight sessions (started 22:00-6:00) | C29: =COUNTIF('Raw - Sessions'!$I$5:$I$292,TRUE()) -> 86
A30: Total days in reporting period | C30: ='Raw - Daily Energy'!A369-'Raw - Daily Energy'!A5+1 -> 365
A31: Distinct nights with at least one overnight session | C31: =SUM('Raw - Sessions'!$S$5:$S$292) -> 61 | D31: Counted directly from Raw - Sessions overnight-flagged rows grouped by calendar date (see Raw - Sessions column R).
A32: % of nights with overnight charging | C32: =C31/C30 -> 0.16712329

Sheet Frequency & Day of Week
A1: How Often the Charger Is Used (All Stations Combined)
A2: "Sessions" is used as the count of visits/uses - the export has no unique driver ID, so repeat visits by the same person cannot be told apart from different people. Formulas pull live from Raw - Sessions.
A5: Sessions by Day of Week
A6: Day of Week | B6: Sessions | C6: % of Total
A7: Monday | B7: =COUNTIF('Raw - Sessions'!$X$5:$X$292,A7) -> 32 | C7: =B7/SUM($B$7:$B$13) -> 0.11111111
A8: Tuesday | B8: =COUNTIF('Raw - Sessions'!$X$5:$X$292,A8) -> 42 | C8: =B8/SUM($B$7:$B$13) -> 0.14583333
A9: Wednesday | B9: =COUNTIF('Raw - Sessions'!$X$5:$X$292,A9) -> 28 | C9: =B9/SUM($B$7:$B$13) -> 0.097222222
A10: Thursday | B10: =COUNTIF('Raw - Sessions'!$X$5:$X$292,A10) -> 32 | C10: =B10/SUM($B$7:$B$13) -> 0.11111111
A11: Friday | B11: =COUNTIF('Raw - Sessions'!$X$5:$X$292,A11) -> 52 | C11: =B11/SUM($B$7:$B$13) -> 0.18055556
A12: Saturday | B12: =COUNTIF('Raw - Sessions'!$X$5:$X$292,A12) -> 53 | C12: =B12/SUM($B$7:$B$13) -> 0.18402778
A13: Sunday | B13: =COUNTIF('Raw - Sessions'!$X$5:$X$292,A13) -> 49 | C13: =B13/SUM($B$7:$B$13) -> 0.17013889
A16: Sessions per Week (Mon-start weeks)
A17: Week Start | B17: Sessions | C17: Energy (kWh) | D17: Revenue ($)
A18: 45943 | B18: =COUNTIF('Raw - Sessions'!$Y$5:$Y$292,A18) -> 3 | C18: =SUMIF('Raw - Sessions'!$Y$5:$Y$292,A18,'Raw - Sessions'!$E$5:$E$292) -> 22.571108 | D18: =SUMIF('Raw - Sessions'!$Y$5:$Y$292,A18,'Raw - Sessions'!$P$5:$P$292) -> 3.53
A19: 45950 | B19: =COUNTIF('Raw - Sessions'!$Y$5:$Y$292,A19) -> 17 | C19: =SUMIF('Raw - Sessions'!$Y$5:$Y$292,A19,'Raw - Sessions'!$E$5:$E$292) -> 225.06146 | D19: =SUMIF('Raw - Sessions'!$Y$5:$Y$292,A19,'Raw - Sessions'!$P$5:$P$292) -> 98.16
A20: 45957 | B20: =COUNTIF('Raw - Sessions'!$Y$5:$Y$292,A20) -> 11 | C20: =SUMIF('Raw - Sessions'!$Y$5:$Y$292,A20,'Raw - Sessions'!$E$5:$E$292) -> 235.2913 | D20: =SUMIF('Raw - Sessions'!$Y$5:$Y$292,A20,'Raw - Sessions'!$P$5:$P$292) -> 126.14
A21: 45964 | B21: =COUNTIF('Raw - Sessions'!$Y$5:$Y$292,A21) -> 6 | C21: =SUMIF('Raw - Sessions'!$Y$5:$Y$292,A21,'Raw - Sessions'!$E$5:$E$292) -> 186.2436 | D21: =SUMIF('Raw - Sessions'!$Y$5:$Y$292,A21,'Raw - Sessions'!$P$5:$P$292) -> 94.05
A22: 45971 | B22: =COUNTIF('Raw - Sessions'!$Y$5:$Y$292,A22) -> 7 | C22: =SUMIF('Raw - Sessions'!$Y$5:$Y$292,A22,'Raw - Sessions'!$E$5:$E$292) -> 182.08606 | D22: =SUMIF('Raw - Sessions'!$Y$5:$Y$292,A22,'Raw - Sessions'!$P$5:$P$292) -> 92.64
A23: 45978 | B23: =COUNTIF('Raw - Sessions'!$Y$5:$Y$292,A23) -> 3 | C23: =SUMIF('Raw - Sessions'!$Y$5:$Y$292,A23,'Raw - Sessions'!$E$5:$E$292) -> 134.1563 | D23: =SUMIF('Raw - Sessions'!$Y$5:$Y$292,A23,'Raw - Sessions'!$P$5:$P$292) -> 70.5
A24: 45985 | B24: =COUNTIF('Raw - Sessions'!$Y$5:$Y$292,A24) -> 9 | C24: =SUMIF('Raw - Sessions'!$Y$5:$Y$292,A24,'Raw - Sessions'!$E$5:$E$292) -> 204.88278 | D24: =SUMIF('Raw - Sessions'!$Y$5:$Y$292,A24,'Raw - Sessions'!$P$5:$P$292) -> 104.89
A25: 45992 | B25: =COUNTIF('Raw - Sessions'!$Y$5:$Y$292,A25) -> 3 | C25: =SUMIF('Raw - Sessions'!$Y$5:$Y$292,A25,'Raw - Sessions'!$E$5:$E$292) -> 45.4715 | D25: =SUMIF('Raw - Sessions'!$Y$5:$Y$292,A25,'Raw - Sessions'!$P$5:$P$292) -> 23.17
A26: 45999 | B26: =COUNTIF('Raw - Sessions'!$Y$5:$Y$292,A26) -> 4 | C26: =SUMIF('Raw - Sessions'!$Y$5:$Y$292,A26,'Raw - Sessions'!$E$5:$E$292) -> 145.33441 | D26: =SUMIF('Raw - Sessions'!$Y$5:$Y$292,A26,'Raw - Sessions'!$P$5:$P$292) -> 104.5
A27: 46006 | B27: =COUNTIF('Raw - Sessions'!$Y$5:$Y$292,A27) -> 11 | C27: =SUMIF('Raw - Sessions'!$Y$5:$Y$292,A27,'Raw - Sessions'!$E$5:$E$292) -> 217.19 | D27: =SUMIF('Raw - Sessions'!$Y$5:$Y$292,A27,'Raw - Sessions'!$P$5:$P$292) -> 138.42
A28: 46013 | B28: =COUNTIF('Raw - Sessions'!$Y$5:$Y$292,A28) -> 14 | C28: =SUMIF('Raw - Sessions'!$Y$5:$Y$292,A28,'Raw - Sessions'!$E$5:$E$292) -> 325.92236 | D28: =SUMIF('Raw - Sessions'!$Y$5:$Y$292,A28,'Raw - Sessions'!$P$5:$P$292) -> 201.67
A29: 46020 | B29: =COUNTIF('Raw - Sessions'!$Y$5:$Y$292,A29) -> 3 | C29: =SUMIF('Raw - Sessions'!$Y$5:$Y$292,A29,'Raw - Sessions'!$E$5:$E$292) -> 42.590099 | D29: =SUMIF('Raw - Sessions'!$Y$5:$Y$292,A29,'Raw - Sessions'!$P$5:$P$292) -> 18.25
... A56: 46209 | B56: =COUNTIF('Raw - Sessions'!$Y$5:$Y$292,A56) -> 2 | C56: =SUMIF('Raw - Sessions'!$Y$5:$Y$292,A56,'Raw - Sessions'!$E$5:$E$292) -> 41.392389 | D56: =SUMIF('Raw - Sessions'!$Y$5:$Y$292,A56,'Raw - Sessions'!$P$5:$P$292) -> 46.17
A57: Average / week | B57: =AVERAGE(B18:B56) -> 7.3846154

Sheet Revenue & Economic Impact
A1: Revenue & Economic Impact (All Stations Combined)
A2: Figures pull live from Raw - Sessions billing columns (Gross/Payout Amount, matched from the Organization Statement export).
A4: Total Gross Revenue | C4: Total Payout to Host | E4: Avg Revenue / Session | G4: Avg $ per kWh Delivered
A5: =SUM('Raw - Sessions'!P5:P292) -> 4036.12 | C5: =SUM('Raw - Sessions'!Q5:Q292) -> 3415.92 | E5: =AVERAGE('Raw - Sessions'!P5:P292) -> 17.174979 | G5: =C5/SUM('Raw - Sessions'!E5:E292) -> 0.54947431
A9: Monthly Trend
A10: Month Start | B10: Sessions | C10: Revenue ($) | D10: Energy (kWh)
A11: 45931 | B11: =COUNTIFS('Raw - Sessions'!$B$5:$B$292,">="&A11,'Raw - Sessions'!$B$5:$B$292,"<"&DATE(YEAR(A11),MONTH(A11)+1,1)) -> 27 | C11: =SUMIFS('Raw - Sessions'!$P$5:$P$292,'Raw - Sessions'!$B$5:$B$292,">="&A11,'Raw - Sessions'!$B$5:$B$292,"<"&DATE(YEAR(A11),MONTH(A11)+1,1)) -> 188.56 | D11: =SUMIFS('Raw - Sessions'!$E$5:$E$292,'Raw - Sessions'!$B$5:$B$292,">="&A11,'Raw - Sessions'!$B$5:$B$292,"<"&DATE(YEAR(A11),MONTH(A11)+1,1)) -> 407.11997
A12: 45962 | B12: =COUNTIFS('Raw - Sessions'!$B$5:$B$292,">="&A12,'Raw - Sessions'!$B$5:$B$292,"<"&DATE(YEAR(A12),MONTH(A12)+1,1)) -> 29 | C12: =SUMIFS('Raw - Sessions'!$P$5:$P$292,'Raw - Sessions'!$B$5:$B$292,">="&A12,'Raw - Sessions'!$B$5:$B$292,"<"&DATE(YEAR(A12),MONTH(A12)+1,1)) -> 401.35 | D12: =SUMIFS('Raw - Sessions'!$E$5:$E$292,'Raw - Sessions'!$B$5:$B$292,">="&A12,'Raw - Sessions'!$B$5:$B$292,"<"&DATE(YEAR(A12),MONTH(A12)+1,1)) -> 783.17265
A13: 45992 | B13: =COUNTIFS('Raw - Sessions'!$B$5:$B$292,">="&A13,'Raw - Sessions'!$B$5:$B$292,"<"&DATE(YEAR(A13),MONTH(A13)+1,1)) -> 33 | C13: =SUMIFS('Raw - Sessions'!$P$5:$P$292,'Raw - Sessions'!$B$5:$B$292,">="&A13,'Raw - Sessions'!$B$5:$B$292,"<"&DATE(YEAR(A13),MONTH(A13)+1,1)) -> 479.65 | D13: =SUMIFS('Raw - Sessions'!$E$5:$E$292,'Raw - Sessions'!$B$5:$B$292,">="&A13,'Raw - Sessions'!$B$5:$B$292,"<"&DATE(YEAR(A13),MONTH(A13)+1,1)) -> 764.13596
A14: 46023 | B14: =COUNTIFS('Raw - Sessions'!$B$5:$B$292,">="&A14,'Raw - Sessions'!$B$5:$B$292,"<"&DATE(YEAR(A14),MONTH(A14)+1,1)) -> 11 | C14: =SUMIFS('Raw - Sessions'!$P$5:$P$292,'Raw - Sessions'!$B$5:$B$292,">="&A14,'Raw - Sessions'!$B$5:$B$292,"<"&DATE(YEAR(A14),MONTH(A14)+1,1)) -> 50.49 | D14: =SUMIFS('Raw - Sessions'!$E$5:$E$292,'Raw - Sessions'!$B$5:$B$292,">="&A14,'Raw - Sessions'!$B$5:$B$292,"<"&DATE(YEAR(A14),MONTH(A14)+1,1)) -> 98.330102
A15: 46054 | B15: =COUNTIFS('Raw - Sessions'!$B$5:$B$292,">="&A15,'Raw - Sessions'!$B$5:$B$292,"<"&DATE(YEAR(A15),MONTH(A15)+1,1)) -> 27 | C15: =SUMIFS('Raw - Sessions'!$P$5:$P$292,'Raw - Sessions'!$B$5:$B$292,">="&A15,'Raw - Sessions'!$B$5:$B$292,"<"&DATE(YEAR(A15),MONTH(A15)+1,1)) -> 503.39 | D15: =SUMIFS('Raw - Sessions'!$E$5:$E$292,'Raw - Sessions'!$B$5:$B$292,">="&A15,'Raw - Sessions'!$B$5:$B$292,"<"&DATE(YEAR(A15),MONTH(A15)+1,1)) -> 807.30535
A16: 46082 | B16: =COUNTIFS('Raw - Sessions'!$B$5:$B$292,">="&A16,'Raw - Sessions'!$B$5:$B$292,"<"&DATE(YEAR(A16),MONTH(A16)+1,1)) -> 21 | C16: =SUMIFS('Raw - Sessions'!$P$5:$P$292,'Raw - Sessions'!$B$5:$B$292,">="&A16,'Raw - Sessions'!$B$5:$B$292,"<"&DATE(YEAR(A16),MONTH(A16)+1,1)) -> 462.35 | D16: =SUMIFS('Raw - Sessions'!$E$5:$E$292,'Raw - Sessions'!$B$5:$B$292,">="&A16,'Raw - Sessions'!$B$5:$B$292,"<"&DATE(YEAR(A16),MONTH(A16)+1,1)) -> 655.18335
A17: 46113 | B17: =COUNTIFS('Raw - Sessions'!$B$5:$B$292,">="&A17,'Raw - Sessions'!$B$5:$B$292,"<"&DATE(YEAR(A17),MONTH(A17)+1,1)) -> 47 | C17: =SUMIFS('Raw - Sessions'!$P$5:$P$292,'Raw - Sessions'!$B$5:$B$292,">="&A17,'Raw - Sessions'!$B$5:$B$292,"<"&DATE(YEAR(A17),MONTH(A17)+1,1)) -> 825.21 | D17: =SUMIFS('Raw - Sessions'!$E$5:$E$292,'Raw - Sessions'!$B$5:$B$292,">="&A17,'Raw - Sessions'!$B$5:$B$292,"<"&DATE(YEAR(A17),MONTH(A17)+1,1)) -> 1195.588
A18: 46143 | B18: =COUNTIFS('Raw - Sessions'!$B$5:$B$292,">="&A18,'Raw - Sessions'!$B$5:$B$292,"<"&DATE(YEAR(A18),MONTH(A18)+1,1)) -> 40 | C18: =SUMIFS('Raw - Sessions'!$P$5:$P$292,'Raw - Sessions'!$B$5:$B$292,">="&A18,'Raw - Sessions'!$B$5:$B$292,"<"&DATE(YEAR(A18),MONTH(A18)+1,1)) -> 606.14 | D18: =SUMIFS('Raw - Sessions'!$E$5:$E$292,'Raw - Sessions'!$B$5:$B$292,">="&A18,'Raw - Sessions'!$B$5:$B$292,"<"&DATE(YEAR(A18),MONTH(A18)+1,1)) -> 818.17509
A19: 46174 | B19: =COUNTIFS('Raw - Sessions'!$B$5:$B$292,">="&A19,'Raw - Sessions'!$B$5:$B$292,"<"&DATE(YEAR(A19),MONTH(A19)+1,1)) -> 46 | C19: =SUMIFS('Raw - Sessions'!$P$5:$P$292,'Raw - Sessions'!$B$5:$B$292,">="&A19,'Raw - Sessions'!$B$5:$B$292,"<"&DATE(YEAR(A19),MONTH(A19)+1,1)) -> 425.72 | D19: =SUMIFS('Raw - Sessions'!$E$5:$E$292,'Raw - Sessions'!$B$5:$B$292,">="&A19,'Raw - Sessions'!$B$5:$B$292,"<"&DATE(YEAR(A19),MONTH(A19)+1,1)) -> 581.79773
A20: 46204 | B20: =COUNTIFS('Raw - Sessions'!$B$5:$B$292,">="&A20,'Raw - Sessions'!$B$5:$B$292,"<"&DATE(YEAR(A20),MONTH(A20)+1,1)) -> 7 | C20: =SUMIFS('Raw - Sessions'!$P$5:$P$292,'Raw - Sessions'!$B$5:$B$292,">="&A20,'Raw - Sessions'!$B$5:$B$292,"<"&DATE(YEAR(A20),MONTH(A20)+1,1)) -> 93.26 | D20: =SUMIFS('Raw - Sessions'!$E$5:$E$292,'Raw - Sessions'!$B$5:$B$292,">="&A20,'Raw - Sessions'!$B$5:$B$292,"<"&DATE(YEAR(A20),MONTH(A20)+1,1)) -> 105.89729
A23: Economic Impact Context (for presentation to the mayor)
A24: This charging site generated the totals above directly through session fees. Separately, published research on EV charging and local business activity provides a benchmark for the wider "dwell time" effect:
A25: A 2024 MIT/Nature Communications study of over 4,000 California charging stations found that installing a charger boosted annual spending at each nearby business by roughly $1,478 (2019 data) to $404 (2021-2023 data), as drivers use charging time to shop or dine nearby (source: MIT News / Nature Communications, "Effects of electric vehicle charging stations on the economic vitality of local businesses," 2024).
A26: The U.S. DOT Rural EV Toolkit similarly notes that because fast charging still takes meaningful time, rural EV drivers tend to combine a charging stop with visits to nearby stores, restaurants, or attractions - a "captive dwell time" that downtown businesses can capture.
A27: ="Barbourville-specific signal: of the "&(COUNTIF('Raw - Sessions'!$O$5:$O$292,"KY")+COUNTIFS('Raw - Sessions'!$O$5:$O$292,"<>",'Raw - Sessions'!$O$5:$O$292,"<>KY"))&" sessions with a known driver location, "&COUNTIF('Raw - Sessions'!$O$5:$O$292,"KY")&" originated in Kentucky and "&COUNTIFS('Raw - Sessions'!$O$5:$O$292,"<>",'Raw - Sessions'!$O$5:$O$292,"<>KY")&" came from other states (see Visitor Origin tab) - consistent with the station drawing highway/through traffic near US-25E, not only local drivers." -> Barbourville-specific signal: of the 164 sessions with a known driver location, 96 originated in Kentucky and 68 came from other states (see Visitor Origin tab) - consistent with the station drawing highway/through traffic near US-25E, not only local drivers.
A28: These figures are provided as directional context, not a Barbourville-specific economic study - the city would need its own downtown-business survey to quantify local spend per charging stop.

Sheet Financial Reconciliation
A1: Financial Reconciliation: What Drivers Pay, What Fees/Taxes Take, What the Owner Keeps
A2: Figures pull live from Raw - Sessions billing/rate columns (matched from the Organization Statement export, 235 of 288 sessions have billing data).
A4: Total Gross (What Drivers Paid) | C4: Total Fees + Taxes Withheld | E4: Total Payout (What Owner Kept) | G4: Fees+Taxes as % of Gross
A5: =SUM('Raw - Sessions'!$P$5:$P$292) -> 4036.12 | C5: =SUM('Raw - Sessions'!$W$5:$W$292) -> 619.21 | E5: =SUM('Raw - Sessions'!$Q$5:$Q$292) -> 3415.92 | G5: =C5/A5 -> 0.15341714
A9: Where the Fees & Taxes Go
A10: Component | B10: Total ($) | C10: What it is
A11: Sales Tax | B11: =SUM('Raw - Sessions'!Z5:Z292) -> 212.16 | C11: State/local sales tax collected on the transaction
A12: Service Fee (ChargePoint) | B12: =SUM('Raw - Sessions'!AE5:AE292) -> 30.57 | C12: ChargePoint's per-session service fee
A13: Flex Billing Service Fee | B13: =SUM('Raw - Sessions'!AD5:AD292) -> 376.48 | C13: ChargePoint's payment-processing fee
A14: Excise Tax | B14: =SUM('Raw - Sessions'!AA5:AA292) -> 0 | C14: Not applied in this dataset (all $0)
A15: Other Taxes | B15: =SUM('Raw - Sessions'!AB5:AB292) -> 0 | C15: Not applied in this dataset (all $0)
A16: Service Fee Tax | B16: =SUM('Raw - Sessions'!AC5:AC292) -> 0 | C16: Not applied in this dataset (all $0)
A17: Every total above is a live SUM formula against Raw - Sessions columns Z:AE - edit a fee/tax value there and these update automatically.
A20: Full Reconciliation Check — Every Session
A21: The posted per-kWh rate changed over time at both stations, per the Pricing Rule Name on each session: $0.25/kWh at launch (Oct 15-21, 2025), $0.40/kWh from Oct 22, 2025 to Mar 8, 2026, and $0.50/kWh from Mar 11, 2026 onward. Multiplying Rate × Energy (kWh) gives the pure energy charge - it does NOT equal the pre-tax session charge (Net Session Fee) for most sessions; the gap grows with session length (correlation with duration ≈ 0.88), consistent with a time-based add-on layered on top of the per-kWh rate (roughly $3.60/hour, R² ≈ 0.97 in a one-time regression against duration - this specific regression is not a live formula, since Excel has no native regression-against-duration function; re-run it in Python if the underlying data changes materially).
A22: ="CHECK 1 — Gross Amount = Net Session Fee + Sales Tax + Service Fee (+ Excise/Other/Service Fee Tax, all $0 here): this reconciles exactly for "&(A27-C27)&" of "&A27&" billed sessions. "&C27&" session(s) fail this check by more than $0.02." -> CHECK 1 — Gross Amount = Net Session Fee + Sales Tax + Service Fee (+ Excise/Other/Service Fee Tax, all $0 here): this reconciles exactly for 235 of 235 billed sessions. 0 session(s) fail this check by more than $0.02.
A23: ="CHECK 2 — Payout Amount = Gross Amount − Service Fee − Flex Billing Service Fee − Sales Tax: this reconciles for "&(A27-E27)&" of "&A27&" billed sessions. "&E27&" session(s) do NOT reconcile and are flagged in red in the table below." -> CHECK 2 — Payout Amount = Gross Amount − Service Fee − Flex Billing Service Fee − Sales Tax: this reconciles for 234 of 235 billed sessions. 1 session(s) do NOT reconcile and are flagged in red in the table below.
A24: =IF(AND(C27=0,E27=0),"✓ All sessions reconcile - no discrepancies found.","⚠ "&(C27+E27)&" check(s) failed - total discrepancy found: $"&TEXT(G27,"0.00")&". Use the filter arrows on the Gross Check / Payout Check columns below to isolate the flagged row(s).") -> ⚠ 1 check(s) failed - total discrepancy found: $0.99. Use the filter arrows on the Gross Check / Payout Check columns below to isolate the flagged row(s).
A26: Billed Sessions Checked | C26: Gross Amount Mismatches | E26: Payout Amount Mismatches | G26: Total $ Discrepancy Found
A27: =COUNT(E31:E318) -> 235 | C27: =COUNTIF(L31:L318,"MISMATCH") -> 0 | E27: =COUNTIF(P31:P318,"MISMATCH") -> 1 | G27: =SUMPRODUCT((L31:L318="MISMATCH")*ABS(N(K31:K318)))+SUMPRODUCT((P31:P318="MISMATCH")*ABS(N(O31:O318))) -> 0.99
A29: Full Reconciliation Table — All 288 Sessions (blank = no billing data for that session)
A30: Session ID | B30: Station | C30: Rate ($/kWh) | D30: Energy (kWh) | E30: Net Session Fee | F30: Sales Tax | G30: Service Fee | H30: Flex Billing Fee | I30: Gross Amount | J30: Calc. Gross | K30: Gross Diff | L30: Gross Check | M30: Payout Amount | N30: Calc. Payout | O30: Payout Diff | P30: Payout Check
A31: ='Raw - Sessions'!A5 -> 4511566811 | B31: ='Raw - Sessions'!K5 -> BARBOURVILLE / TOURISM | C31: =IF(ISBLANK('Raw - Sessions'!U5),"",'Raw - Sessions'!T5) -> 0.25 | D31: ='Raw - Sessions'!E5 -> 8.483508 | E31: =IF(ISBLANK('Raw - Sessions'!U5),"",'Raw - Sessions'!U5) -> 2.12 | F31: =IF(ISBLANK('Raw - Sessions'!U5),"",'Raw - Sessions'!Z5) -> 0.13 | G31: =IF(ISBLANK('Raw - Sessions'!U5),"",'Raw - Sessions'!AE5) -> 0 | H31: =IF(ISBLANK('Raw - Sessions'!U5),"",'Raw - Sessions'!AD5) -> 0.21 | I31: =IF(ISBLANK('Raw - Sessions'!U5),"",'Raw - Sessions'!P5) -> 2.25 | J31: =IF(E31="","",E31+F31+G31+'Raw - Sessions'!AA5+'Raw - Sessions'!AB5+'Raw - Sessions'!AC5) -> 2.25 | K31: =IF(E31="","",I31-J31) -> 0 | L31: =IF(E31="","",IF(ABS(K31)>0.02,"MISMATCH","OK")) -> OK | M31: =IF(ISBLANK('Raw - Sessions'!U5),"",'Raw - Sessions'!Q5) -> 1.91 | N31: =IF(E31="","",I31-G31-H31-F31) -> 1.91 | O31: =IF(E31="","",M31-N31) -> 0 | P31: =IF(E31="","",IF(ABS(O31)>0.02,"MISMATCH","OK")) -> OK
A32: ='Raw - Sessions'!A6 -> 4523627951 | B32: ='Raw - Sessions'!K6 -> BARBOURVILLE / CITY HALL | C32: =IF(ISBLANK('Raw - Sessions'!U6),"",'Raw - Sessions'!T6) -> 0.25 | D32: ='Raw - Sessions'!E6 -> 4.8593 | E32: =IF(ISBLANK('Raw - Sessions'!U6),"",'Raw - Sessions'!U6) -> 1.21 | F32: =IF(ISBLANK('Raw - Sessions'!U6),"",'Raw - Sessions'!Z6) -> 0.07 | G32: =IF(ISBLANK('Raw - Sessions'!U6),"",'Raw - Sessions'!AE6) -> 0 | H32: =IF(ISBLANK('Raw - Sessions'!U6),"",'Raw - Sessions'!AD6) -> 0.12 | I32: =IF(ISBLANK('Raw - Sessions'!U6),"",'Raw - Sessions'!P6) -> 1.28 | J32: =IF(E32="","",E32+F32+G32+'Raw - Sessions'!AA6+'Raw - Sessions'!AB6+'Raw - Sessions'!AC6) -> 1.28 | K32: =IF(E32="","",I32-J32) -> 0 | L32: =IF(E32="","",IF(ABS(K32)>0.02,"MISMATCH","OK")) -> OK | M32: =IF(ISBLANK('Raw - Sessions'!U6),"",'Raw - Sessions'!Q6) -> 1.09 | N32: =IF(E32="","",I32-G32-H32-F32) -> 1.09 | O32: =IF(E32="","",M32-N32) -> 0 | P32: =IF(E32="","",IF(ABS(O32)>0.02,"MISMATCH","OK")) -> OK
A33: ='Raw - Sessions'!A7 -> 4524317961 | B33: ='Raw - Sessions'!K7 -> BARBOURVILLE / CITY HALL | C33: =IF(ISBLANK('Raw - Sessions'!U7),"",'Raw - Sessions'!T7) | D33: ='Raw - Sessions'!E7 -> 9.2283 | E33: =IF(ISBLANK('Raw - Sessions'!U7),"",'Raw - Sessions'!U7) | F33: =IF(ISBLANK('Raw - Sessions'!U7),"",'Raw - Sessions'!Z7) | G33: =IF(ISBLANK('Raw - Sessions'!U7),"",'Raw - Sessions'!AE7) | H33: =IF(ISBLANK('Raw - Sessions'!U7),"",'Raw - Sessions'!AD7) | I33: =IF(ISBLANK('Raw - Sessions'!U7),"",'Raw - Sessions'!P7) | J33: =IF(E33="","",E33+F33+G33+'Raw - Sessions'!AA7+'Raw - Sessions'!AB7+'Raw - Sessions'!AC7) | K33: =IF(E33="","",I33-J33) | L33: =IF(E33="","",IF(ABS(K33)>0.02,"MISMATCH","OK")) | M33: =IF(ISBLANK('Raw - Sessions'!U7),"",'Raw - Sessions'!Q7) | N33: =IF(E33="","",I33-G33-H33-F33) | O33: =IF(E33="","",M33-N33) | P33: =IF(E33="","",IF(ABS(O33)>0.02,"MISMATCH","OK"))
A34: ='Raw - Sessions'!A8 -> 4526984361 | B34: ='Raw - Sessions'!K8 -> BARBOURVILLE / CITY HALL | C34: =IF(ISBLANK('Raw - Sessions'!U8),"",'Raw - Sessions'!T8) | D34: ='Raw - Sessions'!E8 -> 0 | E34: =IF(ISBLANK('Raw - Sessions'!U8),"",'Raw - Sessions'!U8) | F34: =IF(ISBLANK('Raw - Sessions'!U8),"",'Raw - Sessions'!Z8) | G34: =IF(ISBLANK('Raw - Sessions'!U8),"",'Raw - Sessions'!AE8) | H34: =IF(ISBLANK('Raw - Sessions'!U8),"",'Raw - Sessions'!AD8) | I34: =IF(ISBLANK('Raw - Sessions'!U8),"",'Raw - Sessions'!P8) | J34: =IF(E34="","",E34+F34+G34+'Raw - Sessions'!AA8+'Raw - Sessions'!AB8+'Raw - Sessions'!AC8) | K34: =IF(E34="","",I34-J34) | L34: =IF(E34="","",IF(ABS(K34)>0.02,"MISMATCH","OK")) | M34: =IF(ISBLANK('Raw - Sessions'!U8),"",'Raw - Sessions'!Q8) | N34: =IF(E34="","",I34-G34-H34-F34) | O34: =IF(E34="","",M34-N34) | P34: =IF(E34="","",IF(ABS(O34)>0.02,"MISMATCH","OK"))
A35: ='Raw - Sessions'!A9 -> 4526989521 | B35: ='Raw - Sessions'!K9 -> BARBOURVILLE / CITY HALL | C35: =IF(ISBLANK('Raw - Sessions'!U9),"",'Raw - Sessions'!T9) -> 0.25 | D35: ='Raw - Sessions'!E9 -> 26.1175 | E35: =IF(ISBLANK('Raw - Sessions'!U9),"",'Raw - Sessions'!U9) -> 6.53 | F35: =IF(ISBLANK('Raw - Sessions'!U9),"",'Raw - Sessions'!Z9) -> 0.39 | G35: =IF(ISBLANK('Raw - Sessions'!U9),"",'Raw - Sessions'!AE9) -> 0 | H35: =IF(ISBLANK('Raw - Sessions'!U9),"",'Raw - Sessions'!AD9) -> 0.65 | I35: =IF(ISBLANK('Raw - Sessions'!U9),"",'Raw - Sessions'!P9) -> 6.92 | J35: =IF(E35="","",E35+F35+G35+'Raw - Sessions'!AA9+'Raw - Sessions'!AB9+'Raw - Sessions'!AC9) -> 6.92 | K35: =IF(E35="","",I35-J35) -> 0 | L35: =IF(E35="","",IF(ABS(K35)>0.02,"MISMATCH","OK")) -> OK | M35: =IF(ISBLANK('Raw - Sessions'!U9),"",'Raw - Sessions'!Q9) -> 5.88 | N35: =IF(E35="","",I35-G35-H35-F35) -> 5.88 | O35: =IF(E35="","",M35-N35) -> 0 | P35: =IF(E35="","",IF(ABS(O35)>0.02,"MISMATCH","OK")) -> OK
A36: ='Raw - Sessions'!A10 -> 4530183221 | B36: ='Raw - Sessions'!K10 -> BARBOURVILLE / CITY HALL | C36: =IF(ISBLANK('Raw - Sessions'!U10),"",'Raw - Sessions'!T10) -> 0.25 | D36: ='Raw - Sessions'!E10 -> 42.2076 | E36: =IF(ISBLANK('Raw - Sessions'!U10),"",'Raw - Sessions'!U10) -> 10.55 | F36: =IF(ISBLANK('Raw - Sessions'!U10),"",'Raw - Sessions'!Z10) -> 0.63 | G36: =IF(ISBLANK('Raw - Sessions'!U10),"",'Raw - Sessions'!AE10) -> 0 | H36: =IF(ISBLANK('Raw - Sessions'!U10),"",'Raw - Sessions'!AD10) -> 1.05 | I36: =IF(ISBLANK('Raw - Sessions'!U10),"",'Raw - Sessions'!P10) -> 11.18 | J36: =IF(E36="","",E36+F36+G36+'Raw - Sessions'!AA10+'Raw - Sessions'!AB10+'Raw - Sessions'!AC10) -> 11.18 | K36: =IF(E36="","",I36-J36) -> 0 | L36: =IF(E36="","",IF(ABS(K36)>0.02,"MISMATCH","OK")) -> OK | M36: =IF(ISBLANK('Raw - Sessions'!U10),"",'Raw - Sessions'!Q10) -> 9.5 | N36: =IF(E36="","",I36-G36-H36-F36) -> 9.5 | O36: =IF(E36="","",M36-N36) -> 0 | P36: =IF(E36="","",IF(ABS(O36)>0.02,"MISMATCH","OK")) -> OK
